Workbook

Sheet Update guideline
A1: Page 1- For OPM
A38: Page 2 - For Requesters

Sheet Pivot Table 3
L1: Loading
L3: =K3/G3 -> 0
L4: =K4/G4 -> 1
L5: =K5/G5 -> 1
L6: =K6/G6 -> 1
L7: =K7/G7 -> 0
L8: =K8/G8 -> 0
L9: =K9/G9 -> 1
L10: =K10/G10 -> 1
L11: =K11/G11 -> 0
L12: =K12/G12 -> 0
L13: =K13/G13 -> 0
L14: =K14/G14 -> 0
... L168: =K168/G168 -> 1

Sheet G Project Timeline-OPM update
B1: Rule: MVA EQ in-house date will be 2weeks earlier than each stage Date of each stage = OPM release
G2: Update ngày construction finish
D3: Brand | G3: 1st stage | H3: 2nd stage | I3: 3rd stage | J3: 4th stage | K3: 5th stage | L3: 6th stage
D4: SKW | E4: Pre-MLB | F4: proto 0 | G4: P1.0 | H4: P1.1 | I4: EVT | J4: DVT | K4: PVT | L4: MP
B6: Project Year | C6: Project | D6: Phase | G6: Date | H6: Date | I6: Date | J6: Date | K6: Date | L6: Date | M6: OPM DRI | N6: Mail approved Budget
B7: P26 | C7: 4CS4 | D7: SMT | G7: - | H7: - | I7: - | J7: 46076 | K7: 46123 | L7: 46149 | M7: Doris- SMT OPM
B8: P26 | C8: 4CS4 | D8: FATP | G8: - | H8: - | I8: - | J8: 46090 | K8: 46135 | L8: 46149 | M8: OPM- Đức_Ryan
B9: P26 | C9: CGY4 | D9: SMT | G9: - | H9: - | I9: - | J9: 46076 | K9: 46125 | L9: 46149 | M9: Judy Tran
B10: P26 | C10: CGY4 | D10: FATP | G10: - | H10: - | I10: - | J10: 46090 | K10: 46135 | L10: 46149 | M10: thuy Sarah
B11: P26 | C11: PKK4 | D11: SMT | G11: - | H11: - | I11: - | J11: 46076 | K11: 46123 | L11: 46149 | M11: Huong Nguyen - Clara
B12: P26 | C12: PKK4 | D12: FATP | G12: - | H12: - | I12: - | J12: 46090 | K12: 46135 | L12: 46149 | M12: Luyện - Ben
B13: P26 Demo Line | C13: 4CS4 | D13: SMT | I13: 46072 | J13: 46072 | K13: 46123 | L13: 46156 | M13: Doris- SMT OPM
B14: P26 Demo Line | C14: 4CS4 | D14: FATP | I14: 46072 | J14: 46072 | K14: 46135 | L14: 46156 | M14: OPM- Đức_Ryan
B15: P26 Demo Line | C15: CGY4 | D15: SMT | I15: 46072 | J15: 46072 | K15: 46123 | L15: 46156 | M15: Judy Tran
B16: P26 Demo Line | C16: CGY4 | D16: FATP | I16: 46072 | J16: 46072 | K16: 46135 | L16: 46156 | M16: thuy Sarah
B17: P26 Demo Line | C17: PKK4 | D17: SMT | I17: 46072 | J17: 46072 | K17: 46123 | L17: 46156 | M17: Huong Nguyen - Clara
B18: P26 Demo Line | C18: PKK4 | D18: FATP | I18: 46072 | J18: 46072 | K18: 46135 | L18: 46156 | M18: Luyện - Ben
B19: P26 Zombie line | C19: 4CS4 | D19: Zombie | K19: 46165 | L19: 46202 | M19: Jenna Thanh Tam
B20: P26 Zombie line | C20: CGY4 | D20: Zombie | K20: 46165 | L20: 46202 | M20: OPM Hung Tom
B21: P26 Zombie line | C21: PKK4 | D21: Zombie | K21: 46165 | L21: 46202 | M21: Kayla Thùy Dương
B22: P26 Service line | C22: 4CS4 | D22: SMT | K22: 46144 | L22: 46149 | M22: Tiffany Tiên
B23: P26 Service line | C23: 4CS4 | D23: FATP | L23: 46160 | M23: Thomas OPM Thanh
B24: P26 Service line | C24: CGY4 | D24: SMT | K24: 46144 | L24: 46149 | M24: Tiffany Tiên
B25: P26 Service line | C25: CGY4 | D25: FATP | L25: 46160 | M25: Thomas OPM Thanh
B26: P26 Service line | C26: PKK4 | D26: SMT | K26: 46144 | L26: 46149 | M26: Tiffany Tiên
A27: Add | B27: P26 Service line | C27: PKK4 | D27: FATP | L27: 46160 | M27: Thomas OPM Thanh
A28: Repair-A Quan | B28: P27 | C28: WGO5 | D28: SMT | G28: 46172 | H28: 46208 | I28: 46285 | J28: 46419 | K28: 46124 | M28: Tina Nguyen - OPM SMT
A29: Packing-OPM | B29: P27 | C29: WGO5 | D29: FATP | G29: 46174 | H29: 46216 | I29: 46300 | J29: 46426 | K29: 46124 | M29: Katy Nguyen Thuy Duong
B30: P27 | C30: ASK5 | D30: SMT | G30: 46172 | H30: 46208 | I30: 46285 | J30: 46419 | K30: 46124 | M30: Tina Nguyen - OPM SMT
B31: P27 | C31: ASK5 | D31: FATP | G31: 46174 | H31: 46216 | I31: 46300 | J31: 46426 | K31: 46124 | M31: Linh Nguyen G-OPM
B32: P27 | C32: KSH5 | D32: SMT | G32: 46172 | H32: 46208 | I32: 46285 | J32: 46419 | K32: 46124 | M32: Tina Nguyen - OPM SMT
B33: P27 | C33: KSH5 | D33: FATP | G33: 46174 | H33: 46216 | I33: 46300 | J33: 46426 | K33: 46124 | M33: Anh Thảo -Tiffany
B34: F27 | C34: MCN5 | D34: SMT | E34: 46120 | F34: 46154 | G34: 46167 | H34: 46224 | I34: 46304 | J34: 46436 | K34: 46493 | M34: Minhi Nguyen - OPM SMT
B35: F27 | C35: MCN5 | D35: FATP | F35: 46140 | G35: 46167 | H35: 46223 | I35: 46305 | J35: 46437 | M35: Jessie Nguyen OPM
B36: P25 Service line | C36: MT5 | D36: FATP
B37: P25 Service line | C37: BZ5 | D37: FATP
B38: P25 Service line | C38: FL5 | D38: FATP
B39: P25 Service line | C39: MT5 | D39: SMT
B40: P25 Service line | C40: BZ5 | D40: SMT
B41: P25 Service line | C41: FL5 | D41: SMT

Sheet G Project MVA EQ Request 
A1: Date of Request | B1: Department | C1: Requester name | D1: Requester employee ID | E1: Email | F1: Phone | G1: Item | H1: Request equipment spec | I1: Price | J1: Quantity | K1: Total Cost | L1: Purpose | M1: Year Project | N1: Project | O1: Process | P1: Stage | Q1: Required Delivery Date (update by DRI) | R1: Given LT (days) (follow DRI update) | S1: Required Delivery Date follow Stage date (line open date - 14 days) | T1: Given LT (days) follow stage date | U1: Total Leadtime | V1: Request Deadline | W1: LT theo ngày request of DRI | X1: Late/ ontime | Y1: Action | Z1: Remark | AA1: Budget Status | AB1: Budget # | AC1: PR Status | AD1: PR # | AE1: PO Status | AF1: PO # | AG1: ETA (Plan) | AH1: DTA (Actual) | AI1: #PUR request No | AJ1: Pending reason (If have) | AK1: Action for delivery later than time Setup line | AL1: Qty Done Budget | AM1: Qty Done PR | AN1: Qty Done PO | AO1: Qty Recieved
A2: 46034 | B2: MFG | C2: To Thi Phuong Anh | D2: V1524505 | E2: Phuong Anh To | F2: 4327 | G2: Mini PC (Assy) | H2: =vlookup(G2,'Bidding list 26'!$B$4:$G$270,6,0) -> #N/A | I2: 7800000 | J2: 49 | K2: =I2*J2 -> 382200000 | L2: P26 Demo Line | M2: P26 Demo Line | N2: 4CS4 | O2: FATP | P2: DVT | Q2: 46065 | R2: =Q2-A2 -> 31 | S2: {=INDEX('G Project Timeline-OPM update'!$G$7:$L$35,MATCH(1,('G Project Timeline-OPM update'!$C$7:$C$35=N2)*('G Project Timeline-OPM update'!$B$7:$B$35=M2)*('G Project Timeline-OPM update'!$D$7:$D$35=O2),0),MATCH(P2,'G Project Timeline-OPM update'!$G$4:$L$4,0))-14} -> 46058 | T2: =S2-A2 -> 24 | U2: =IFERROR(VLOOKUP(G2,'Bidding list 26'!$B$2:$P$31,15,0),"") | V2: =S2-U2 -> 46058 | X2: =if(A2>V2,"Late", "On time") -> On time | Y2: New Buy | AA2: Done | AC2: Done | AE2: Done | AF2: 1FSHQ10118 | AH2: =vlookup(AF2,Sheet9!A:D,3,0) -> Đã nhận 11.03.2026 | AI2: EPR2601310006 | AL2: =if(AA2="Done",$J2,0) -> 49 | AM2: =if(AC2="Done",$J2,0) -> 49 | AN2: =if(AE2="Done",$J2,0) -> 49 | AO2: =if(AH2<>"",$J2,0) -> 49
A3: 46034 | B3: MFG | C3: To Thi Phuong Anh | D3: V1524505 | E3: Phuong Anh To | F3: 4327 | G3: Monitor (White)+ ARM | H3: =vlookup(G3,'Bidding list 26'!$B$4:$G$270,6,0) -> HKC MB24V7-W, 23.8 inch White, With Bracket Arm Warrior WA-MH0802 (White) | I3: 1815000 | J3: 49 | K3: =I3*J3 -> 88935000 | L3: P26 Demo Line | M3: P26 Demo Line | N3: 4CS4 | O3: FATP | P3: DVT | Q3: 46065 | R3: =Q3-A3 -> 31 | S3: {=INDEX('G Project Timeline-OPM update'!$G$7:$L$35,MATCH(1,('G Project Timeline-OPM update'!$C$7:$C$35=N3)*('G Project Timeline-OPM update'!$B$7:$B$35=M3)*('G Project Timeline-OPM update'!$D$7:$D$35=O3),0),MATCH(P3,'G Project Timeline-OPM update'!$G$4:$L$4,0))-14} -> 46058 | T3: =S3-A3 -> 24 | U3: =IFERROR(VLOOKUP(G3,'Bidding list 26'!$B$2:$P$31,15,0),"") -> 80 | V3: =S3-U3 -> 45978 | X3: =if(A3>V3,"Late", "On time") -> Late | Y3: New Buy | AA3: Done | AC3: Done | AE3: Done | AF3: 1FSHQ10079 | AH3: 46073 | AI3: EPR2601310007 | AL3: =if(AA3="Done",$J3,0) -> 49 | AM3: =if(AC3="Done",$J3,0) -> 49 | AN3: =if(AE3="Done",$J3,0) -> 49 | AO3: =if(AH3<>"",$J3,0) -> 49
A4: 46035 | B4: QA | C4: Ngô Thị Hoa | D4: V1524668 | E4: Hoa (Hana) | G4: Mini PC (Assy) | H4: =vlookup(G4,'Bidding list 26'!$B$4:$G$270,6,0) -> #N/A | I4: 7800000 | J4: 23 | K4: =I4*J4 -> 179400000 | L4: P26 Demo Line | M4: P26 Demo Line | N4: 4CS4 | O4: FATP | P4: EVT | Q4: 46065 | R4: =Q4-A4 -> 30 | S4: {=INDEX('G Project Timeline-OPM update'!$G$7:$L$35,MATCH(1,('G Project Timeline-OPM update'!$C$7:$C$35=N4)*('G Project Timeline-OPM update'!$B$7:$B$35=M4)*('G Project Timeline-OPM update'!$D$7:$D$35=O4),0),MATCH(P4,'G Project Timeline-OPM update'!$G$4:$L$4,0))-14} -> 46058 | T4: =S4-A4 -> 23 | U4: =IFERROR(VLOOKUP(G4,'Bidding list 26'!$B$2:$P$31,15,0),"") | V4: =S4-U4 -> 46058 | X4: =if(A4>V4,"Late", "On time") -> On time | Y4: New Buy | AA4: Done | AC4: Done | AE4: Done | AF4: 1FSHQ10118 | AH4: =vlookup(AF4,Sheet9!A:D,3,0) -> Đã nhận 11.03.2026 | AI4: EPR2602020001 | AL4: =if(AA4="Done",$J4,0) -> 23 | AM4: =if(AC4="Done",$J4,0) -> 23 | AN4: =if(AE4="Done",$J4,0) -> 23 | AO4: =if(AH4<>"",$J4,0) -> 23
A5: 46035 | B5: QA | C5: Ngô Thị Hoa | D5: V1524668 | E5: Hoa (Hana) | G5: Monitor (White)+ ARM | H5: =vlookup(G5,'Bidding list 26'!$B$4:$G$270,6,0) -> HKC MB24V7-W, 23.8 inch White, With Bracket Arm Warrior WA-MH0802 (White) | I5: 1815000 | J5: 23 | K5: =I5*J5 -> 41745000 | L5: P26 Demo Line | M5: P26 Demo Line | N5: 4CS4 | O5: FATP | P5: EVT | Q5: 46065 | R5: =Q5-A5 -> 30 | S5: {=INDEX('G Project Timeline-OPM update'!$G$7:$L$35,MATCH(1,('G Project Timeline-OPM update'!$C$7:$C$35=N5)*('G Project Timeline-OPM update'!$B$7:$B$35=M5)*('G Project Timeline-OPM update'!$D$7:$D$35=O5),0),MATCH(P5,'G Project Timeline-OPM update'!$G$4:$L$4,0))-14} -> 46058 | T5: =S5-A5 -> 23 | U5: =IFERROR(VLOOKUP(G5,'Bidding list 26'!$B$2:$P$31,15,0),"") -> 80 | V5: =S5-U5 -> 45978 | X5: =if(A5>V5,"Late", "On time") -> Late | Y5: New Buy | AA5: Done | AC5: Done | AE5: Done | AF5: 1FSHQ10079 | AH5: 46073 | AI5: EPR2602020002 | AL5: =if(AA5="Done",$J5,0) -> 23 | AM5: =if(AC5="Done",$J5,0) -> 23 | AN5: =if(AE5="Done",$J5,0) -> 23 | AO5: =if(AH5<>"",$J5,0) -> 23
A6: 46035 | B6: TE | C6: Nguyen Trung Kien | D6: V1524574 | E6: kiennt1@fih-foxconn.com | G6: Monitor (White)+ ARM | H6: =vlookup(G6,'Bidding list 26'!$B$4:$G$270,6,0) -> HKC MB24V7-W, 23.8 inch White, With Bracket Arm Warrior WA-MH0802 (White) | I6: 1815000 | J6: 6 | K6: =I6*J6 -> 10890000 | L6: P26 Demo Line | M6: P26 Demo Line | N6: 4CS4 | O6: FATP | P6: EVT | Q6: 46076 | R6: =Q6-A6 -> 41 | S6: {=INDEX('G Project Timeline-OPM update'!$G$7:$L$35,MATCH(1,('G Project Timeline-OPM update'!$C$7:$C$35=N6)*('G Project Timeline-OPM update'!$B$7:$B$35=M6)*('G Project Timeline-OPM update'!$D$7:$D$35=O6),0),MATCH(P6,'G Project Timeline-OPM update'!$G$4:$L$4,0))-14} -> 46058 | T6: =S6-A6 -> 23 | U6: =IFERROR(VLOOKUP(G6,'Bidding list 26'!$B$2:$P$31,15,0),"") -> 80 | V6: =S6-U6 -> 45978 | X6: =if(A6>V6,"Late", "On time") -> Late | Y6: New Buy | AA6: Done | AC6: Done | AE6: Done | AF6: 1FSHQ10079 | AH6: 46073 | AI6: EPR2602020003 | AL6: =if(AA6="Done",$J6,0) -> 6 | AM6: =if(AC6="Done",$J6,0) -> 6 | AN6: =if(AE6="Done",$J6,0) -> 6 | AO6: =if(AH6<>"",$J6,0) -> 6
A7: 46035 | B7: TE | C7: Nguyen Trung Kien | D7: V1524574 | E7: kiennt1@fih-foxconn.com | G7: Mini PC (Assy) | H7: =vlookup(G7,'Bidding list 26'!$B$4:$G$270,6,0) -> #N/A | I7: 7800000 | J7: 6 | K7: =I7*J7 -> 46800000 | L7: P26 Demo Line | M7: P26 Demo Line | N7: 4CS4 | O7: FATP | P7: EVT | Q7: 46076 | R7: =Q7-A7 -> 41 | S7: {=INDEX('G Project Timeline-OPM update'!$G$7:$L$35,MATCH(1,('G Project Timeline-OPM update'!$C$7:$C$35=N7)*('G Project Timeline-OPM update'!$B$7:$B$35=M7)*('G Project Timeline-OPM update'!$D$7:$D$35=O7),0),MATCH(P7,'G Project Timeline-OPM update'!$G$4:$L$4,0))-14} -> 46058 | T7: =S7-A7 -> 23 | U7: =IFERROR(VLOOKUP(G7,'Bidding list 26'!$B$2:$P$31,15,0),"") | V7: =S7-U7 -> 46058 | X7: =if(A7>V7,"Late", "On time") -> On time | Y7: New Buy | AA7: Done | AC7: Done | AE7: Done | AF7: 1FSHQ10118 | AH7: =vlookup(AF7,Sheet9!A:D,3,0) -> Đã nhận 11.03.2026 | AI7: EPR2602020004 | AL7: =if(AA7="Done",$J7,0) -> 6 | AM7: =if(AC7="Done",$J7,0) -> 6 | AN7: =if(AE7="Done",$J7,0) -> 6 | AO7: =if(AH7<>"",$J7,0) -> 6
A8: 46041 | B8: ENG3 | C8: Nguyen Van Huynh | D8: V1536667 | E8: Nguyễn Seven (Huỳnh) | F8: 4500 | G8: IPC+ | H8: =vlookup(G8,'Bidding list 26'!$B$4:$G$270,6,0) -> #N/A | I8: 14200000 | J8: 5 | K8: =I8*J8 -> 71000000 | L8: PC for Auto charging machine P26 | M8: P26 | N8: 4CS4 | O8: FATP | P8: DVT | Q8: 46052 | R8: =Q8-A8 -> 11 | S8: {=INDEX('G Project Timeline-OPM update'!$G$7:$L$35,MATCH(1,('G Project Timeline-OPM update'!$C$7:$C$35=N8)*('G Project Timeline-OPM update'!$B$7:$B$35=M8)*('G Project Timeline-OPM update'!$D$7:$D$35=O8),0),MATCH(P8,'G Project Timeline-OPM update'!$G$4:$L$4,0))-14} -> 46076 | T8: =S8-A8 -> 35 | U8: =IFERROR(VLOOKUP(G8,'Bidding list 26'!$B$2:$P$31,15,0),"") | V8: =S8-U8 -> 46076 | X8: =if(A8>V8,"Late", "On time") -> On time | Y8: New Buy | AA8: Done | AB8: FATP-NPI-P26-MVA2601-104OM | AC8: Done | AD8: 1FSHQ10126 | AE8: Done | AF8: 1FSHQ10126 | AH8: 46073 | AI8: EPR2601310001: Done | AL8: =if(AA8="Done",$J8,0) -> 5 | AM8: =if(AC8="Done",$J8,0) -> 5 | AN8: =if(AE8="Done",$J8,0) -> 5 | AO8: =if(AH8<>"",$J8,0) -> 5
A9: 46041 | B9: ENG3 | C9: Nguyen Van Huynh | D9: V1536667 | E9: Nguyễn Seven (Huỳnh) | F9: 4500 | G9: IPC+ | H9: =vlookup(G9,'Bidding list 26'!$B$4:$G$270,6,0) -> #N/A | I9: 14200000 | J9: 5 | K9: =I9*J9 -> 71000000 | L9: PC for Auto charging machine P26 | M9: P26 | N9: PKK4 | O9: FATP | P9: DVT | Q9: 46052 | R9: =Q9-A9 -> 11 | S9: {=INDEX('G Project Timeline-OPM update'!$G$7:$L$35,MATCH(1,('G Project Timeline-OPM update'!$C$7:$C$35=N9)*('G Project Timeline-OPM update'!$B$7:$B$35=M9)*('G Project Timeline-OPM update'!$D$7:$D$35=O9),0),MATCH(P9,'G Project Timeline-OPM update'!$G$4:$L$4,0))-14} -> 46076 | T9: =S9-A9 -> 35 | U9: =IFERROR(VLOOKUP(G9,'Bidding list 26'!$B$2:$P$31,15,0),"") | V9: =S9-U9 -> 46076 | X9: =if(A9>V9,"Late", "On time") -> On time | Y9: New Buy | AA9: Done | AB9: FATP-NPI-P26-MVA2601-104OM | AC9: Done | AD9: 1FSHQ10127 | AE9: Done | AF9: 1FSHQ10126 | AH9: 46073 | AI9: EPR2601310002: Done | AL9: =if(AA9="Done",$J9,0) -> 5 | AM9: =if(AC9="Done",$J9,0) -> 5 | AN9: =if(AE9="Done",$J9,0) -> 5 | AO9: =if(AH9<>"",$J9,0) -> 5
A10: 46041 | B10: ENG3 | C10: Nguyen Van Huynh | D10: V1536667 | E10: Nguyễn Seven (Huỳnh) | F10: 4500 | G10: IPC+ | H10: =vlookup(G10,'Bidding list 26'!$B$4:$G$270,6,0) -> #N/A | I10: 14200000 | J10: 5 | K10: =I10*J10 -> 71000000 | L10: PC for Auto charging machine P26 | M10: P26 | N10: CGY4 | O10: FATP | P10: DVT | Q10: 46052 | R10: =Q10-A10 -> 11 | S10: {=INDEX('G Project Timeline-OPM update'!$G$7:$L$35,MATCH(1,('G Project Timeline-OPM update'!$C$7:$C$35=N10)*('G Project Timeline-OPM update'!$B$7:$B$35=M10)*('G Project Timeline-OPM update'!$D$7:$D$35=O10),0),MATCH(P10,'G Project Timeline-OPM update'!$G$4:$L$4,0))-14} -> 46076 | T10: =S10-A10 -> 35 | U10: =IFERROR(VLOOKUP(G10,'Bidding list 26'!$B$2:$P$31,15,0),"") | V10: =S10-U10 -> 46076 | X10: =if(A10>V10,"Late", "On time") -> On time | Y10: New Buy | AA10: Done | AB10: FATP-NPI-P26-MVA2601-104OM | AC10: Done | AD10: 1FSHQ10128 | AE10: Done | AF10: 1FSHQ10126 | AH10: 46073 | AI10: EPR2601310003: Done | AL10: =if(AA10="Done",$J10,0) -> 5 | AM10: =if(AC10="Done",$J10,0) -> 5 | AN10: =if(AE10="Done",$J10,0) -> 5 | AO10: =if(AH10<>"",$J10,0) -> 5
A11: 46058 | B11: REL | C11: Laymu Chen | D11: 504000 | E11: LaymuTHChen@fih-foxconn.com | G11: IPC | H11: =vlookup(G11,'Bidding list 26'!$B$4:$G$270,6,0) -> #N/A | I11: 10870000 | J11: 2 | K11: =I11*J11 -> 21740000 | L11: P26 | M11: P26 | N11: 4CS4 | O11: SMT | P11: DVT | Q11: 46064 | R11: =Q11-A11 -> 6 | S11: {=INDEX('G Project Timeline-OPM update'!$G$7:$L$35,MATCH(1,('G Project Timeline-OPM update'!$C$7:$C$35=N11)*('G Project Timeline-OPM update'!$B$7:$B$35=M11)*('G Project Timeline-OPM update'!$D$7:$D$35=O11),0),MATCH(P11,'G Project Timeline-OPM update'!$G$4:$L$4,0))-14} -> 46062 | T11: =S11-A11 -> 4 | U11: =IFERROR(VLOOKUP(G11,'Bidding list 26'!$B$2:$P$31,15,0),"") | V11: =S11-U11 -> 46062 | X11: =if(A11>V11,"Late", "On time") -> On time | Y11: Leverage | AA11: Done | AC11: Done | AE11: Done | AH11: 46064 | AI11: EPR2602060002 : Done / tầm T7 trả | AK11: Tháng 7 trả? | AL11: =if(AA11="Done",$J11,0) -> 2 | AM11: =if(AC11="Done",$J11,0) -> 2 | AN11: =if(AE11="Done",$J11,0) -> 2 | AO11: =if(AH11<>"",$J11,0) -> 2
A12: 46058 | B12: REL | C12: Laymu Chen | D12: 504000 | E12: LaymuTHChen@fih-foxconn.com | G12: Monitor 2 | H12: =vlookup(G12,'Bidding list 26'!$B$4:$G$270,6,0) -> VA1903H-2, 19 inch, VGA cable + HDMI cable / Brand: VIEWSONIC | I12: 1240000 | J12: 7 | K12: =I12*J12 -> 8680000 | L12: P26 | M12: P26 | N12: 4CS4 | O12: SMT | P12: DVT | Q12: 46064 | R12: =Q12-A12 -> 6 | S12: {=INDEX('G Project Timeline-OPM update'!$G$7:$L$35,MATCH(1,('G Project Timeline-OPM update'!$C$7:$C$35=N12)*('G Project Timeline-OPM update'!$B$7:$B$35=M12)*('G Project Timeline-OPM update'!$D$7:$D$35=O12),0),MATCH(P12,'G Project Timeline-OPM update'!$G$4:$L$4,0))-14} -> 46062 | T12: =S12-A12 -> 4 | U12: =IFERROR(VLOOKUP(G12,'Bidding list 26'!$B$2:$P$31,15,0),"") -> 50 | V12: =S12-U12 -> 46012 | X12: =if(A12>V12,"Late", "On time") -> Late | Y12: Leverage | AA12: Done | AC12: Done | AE12: Done | AH12: 111807 | AI12: EPR2602060003 Done / tầm T7 trả | AK12: Tháng 7 trả? | AL12: =if(AA12="Done",$J12,0) -> 7 | AM12: =if(AC12="Done",$J12,0) -> 7 | AN12: =if(AE12="Done",$J12,0) -> 7 | AO12: =if(AH12<>"",$J12,0) -> 7
A13: 46080 | B13: MFG | C13: To Thi Phuong Anh | D13: V1524505 | E13: Phuong Anh To | G13: Monitor 2 | H13: =vlookup(G13,'Bidding list 26'!$B$4:$G$270,6,0) -> VA1903H-2, 19 inch, VGA cable + HDMI cable / Brand: VIEWSONIC | I13: 1240000 | J13: 31 | K13: =I13*J13 -> 38440000 | L13: PKK4 | M13: P26 | N13: PKK4 | O13: FATP | P13: MP | Q13: 46123 | R13: =Q13-A13 -> 43 | S13: {=INDEX('G Project Timeline-OPM update'!$G$7:$L$35,MATCH(1,('G Project Timeline-OPM update'!$C$7:$C$35=N13)*('G Project Timeline-OPM update'!$B$7:$B$35=M13)*('G Project Timeline-OPM update'!$D$7:$D$35=O13),0),MATCH(P13,'G Project Timeline-OPM update'!$G$4:$L$4,0))-14} -> 46135 | T13: =S13-A13 -> 55 | U13: =IFERROR(VLOOKUP(G13,'Bidding list 26'!$B$2:$P$31,15,0),"") -> 50 | V13: =S13-U13 -> 46085 | W13: =A13+U13 -> 46130 | X13: =if(A13>V13,"Late", "On time") -> On time | Y13: New Buy | AA13: Done | AB13: FATP-MP-PKK4-MVA2603-03OM | AC13: Done | AD13: 1FSHQ30084 | AE13: Done | AF13: 1FSHQ30084 | AG13: 46144 | AH13: 46144 | AI13: EPR2603070011 | AL13: =if(AA13="Done",$J13,0) -> 31 | AM13: =if(AC13="Done",$J13,0) -> 31 | AN13: =if(AE13="Done",$J13,0) -> 31 | AO13: =if(#REF!<>"",$J13,0) -> #REF!
A14: 46080 | B14: MFG | C14: To Thi Phuong Anh | D14: V1524505 | E14: Phuong Anh To | G14: Mini PC (Assy) | H14: =vlookup(G14,'Bidding list 26'!$B$4:$G$270,6,0) -> #N/A | I14: 7800000 | J14: 31 | K14: =I14*J14 -> 241800000 | L14: PKK4 | M14: P26 | N14: PKK4 | O14: FATP | P14: MP | Q14: 46123 | R14: =Q14-A14 -> 43 | S14: {=INDEX('G Project Timeline-OPM update'!$G$7:$L$35,MATCH(1,('G Project Timeline-OPM update'!$C$7:$C$35=N14)*('G Project Timeline-OPM update'!$B$7:$B$35=M14)*('G Project Timeline-OPM update'!$D$7:$D$35=O14),0),MATCH(P14,'G Project Timeline-OPM update'!$G$4:$L$4,0))-14} -> 46135 | T14: =S14-A14 -> 55 | U14: =IFERROR(VLOOKUP(G14,'Bidding list 26'!$B$2:$P$31,15,0),"") | V14: =S14-U14 -> 46135 | W14: =A14+U14 -> 46080 | X14: =if(A14>V14,"Late", "On time") -> On time | Y14: New Buy | AA14: Done | AB14: FATP-MP-PKK4-MVA2603-03OM | AC14: Done | AD14: 1FSHQ30085 | AE14: Done | AF14: 1FSHQ30085 | AI14: EPR2603070012 | AL14: =if(AA14="Done",$J14,0) -> 31 | AM14: =if(AC14="Done",$J14,0) -> 31 | AN14: =if(AE14="Done",$J14,0) -> 31 | AO14: =if(AH13<>"",$J14,0) -> 31
A15: 46080 | B15: MFG | C15: To Thi Phuong Anh | D15: V1524505 | E15: Phuong Anh To | G15: Barcode Scanner SEUIC HS505DP, USB cable | H15: =vlookup(G15,'Bidding list 26'!$B$4:$G$270,6,0) -> HS505DP, USB cable | I15: 2300000 | J15: 31 | K15: =I15*J15 -> 71300000 | L15: PKK4 | M15: P26 | N15: PKK4 | O15: FATP | P15: MP | Q15: 46123 | R15: =Q15-A15 -> 43 | S15: {=INDEX('G Project Timeline-OPM update'!$G$7:$L$35,MATCH(1,('G Project Timeline-OPM update'!$C$7:$C$35=N15)*('G Project Timeline-OPM update'!$B$7:$B$35=M15)*('G Project Timeline-OPM update'!$D$7:$D$35=O15),0),MATCH(P15,'G Project Timeline-OPM update'!$G$4:$L$4,0))-14} -> 46135 | T15: =S15-A15 -> 55 | U15: =IFERROR(VLOOKUP(G15,'Bidding list 26'!$B$2:$P$31,15,0),"") -> 50 | V15: =S15-U15 -> 46085 | W15: =A15+U15 -> 46130 | X15: =if(A15>V15,"Late", "On time") -> On time | Y15: New Buy | AA15: Done | AB15: FATP-MP-PKK4-MVA2603-28OM | AC15: Done | AD15: VNPR202604040096 | AE15: Done | AF15: VNPO202604160162 | AG15: 46171 | AH15: 46172 | AI15: EPR2603210009 | AL15: =if(AA15="Done",$J15,0) -> 31 | AM15: =if(AC15="Done",$J15,0) -> 31 | AN15: =if(AE15="Done",$J15,0) -> 31 | AO15: =if(AH15<>"",$J15,0) -> 31
A16: 46080 | B16: MFG | C16: To Thi Phuong Anh | D16: V1524505 | E16: Phuong Anh To | G16: Barcode Printer ZEBRA | H16: =vlookup(G16,'Bidding list 26'!$B$4:$G$270,6,0) -> ZT610, 600dpi | I16: 48800000 | J16: 21 | K16: =I16*J16 -> 1024800000 | L16: PKK4 | M16: P26 | N16: PKK4 | O16: FATP | P16: MP | Q16: 46123 | R16: =Q16-A16 -> 43 | S16: {=INDEX('G Project Timeline-OPM update'!$G$7:$L$35,MATCH(1,('G Project Timeline-OPM update'!$C$7:$C$35=N16)*('G Project Timeline-OPM update'!$B$7:$B$35=M16)*('G Project Timeline-OPM update'!$D$7:$D$35=O16),0),MATCH(P16,'G Project Timeline-OPM update'!$G$4:$L$4,0))-14} -> 46135 | T16: =S16-A16 -> 55 | U16: =IFERROR(VLOOKUP(G16,'Bidding list 26'!$B$2:$P$31,15,0),"") -> 50 | V16: =S16-U16 -> 46085 | W16: =A16+U16 -> 46130 | X16: =if(A16>V16,"Late", "On time") -> On time | Y16: New Buy | AA16: Done | AB16: FATP-MP-PKK4-MVA2603-03OM | AC16: Done | AD16: 1FSHQ30087 | AE16: Done | AF16: 1FSHQ30087 | AG16: pending | AH16: =vlookup(AF16,Sheet9!A:D,3,0) | AI16: EPR2603070013 | AK16: Lấy 16x 1FSHQ20007 => Trả hàng trước | AL16: =if(AA16="Done",$J16,0) -> 21 | AM16: =if(AC16="Done",$J16,0) -> 21 | AN16: =if(AE16="Done",$J16,0) -> 21 | AO16: =if(AH16<>"",$J16,0) -> 0
A17: 46080 | B17: MFG | C17: To Thi Phuong Anh | D17: V1524505 | E17: Phuong Anh To | G17: Monitor 2 | H17: =vlookup(G17,'Bidding list 26'!$B$4:$G$270,6,0) -> VA1903H-2, 19 inch, VGA cable + HDMI cable / Brand: VIEWSONIC | I17: 1240000 | J17: 138 | K17: =I17*J17 -> 171120000 | L17: 4CS4 | M17: P26 | N17: 4CS4 | O17: FATP | P17: MP | Q17: 46123 | R17: =Q17-A17 -> 43 | S17: {=INDEX('G Project Timeline-OPM update'!$G$7:$L$35,MATCH(1,('G Project Timeline-OPM update'!$C$7:$C$35=N17)*('G Project Timeline-OPM update'!$B$7:$B$35=M17)*('G Project Timeline-OPM update'!$D$7:$D$35=O17),0),MATCH(P17,'G Project Timeline-OPM update'!$G$4:$L$4,0))-14} -> 46135 | T17: =S17-A17 -> 55 | U17: =IFERROR(VLOOKUP(G17,'Bidding list 26'!$B$2:$P$31,15,0),"") -> 50 | V17: =S17-U17 -> 46085 | W17: =A17+U17 -> 46130 | X17: =if(A17>V17,"Late", "On time") -> On time | Y17: New Buy | AA17: Done | AB17: FATP-MP-4CS4-MVA2603-04OM | AC17: Done | AD17: 1FSHQ30096 | AE17: Done | AF17: 1FSHQ30096 | AG17: EPR2603070014 request này của MFG P26 có 138x màn hình. Chị lấy đơn 1FSHQ40007 & 1FSHQ30117 : 38 + 6 =44x Trả đơn trước cho P26 MFG | AH17: 85x out ngày 10.06.2026 | AI17: EPR2603070014 | AL17: =if(AA17="Done",$J17,0) -> 138 | AM17: =if(AC17="Done",$J17,0) -> 138 | AN17: =if(AE17="Done",$J17,0) -> 138 | AO17: =if(AH17<>"",$J17,0) -> 138
A18: 46080 | B18: MFG | C18: To Thi Phuong Anh | D18: V1524505 | E18: Phuong Anh To | G18: Mini PC (Assy) | H18: =vlookup(G18,'Bidding list 26'!$B$4:$G$270,6,0) -> #N/A | I18: 7800000 | J18: 163 | K18: =I18*J18 -> 1271400000 | L18: 4CS4 | M18: P26 | N18: 4CS4 | O18: FATP | P18: MP | Q18: 46123 | R18: =Q18-A18 -> 43 | S18: {=INDEX('G Project Timeline-OPM update'!$G$7:$L$35,MATCH(1,('G Project Timeline-OPM update'!$C$7:$C$35=N18)*('G Project Timeline-OPM update'!$B$7:$B$35=M18)*('G Project Timeline-OPM update'!$D$7:$D$35=O18),0),MATCH(P18,'G Project Timeline-OPM update'!$G$4:$L$4,0))-14} -> 46135 | T18: =S18-A18 -> 55 | U18: =IFERROR(VLOOKUP(G18,'Bidding list 26'!$B$2:$P$31,15,0),"") | V18: =S18-U18 -> 46135 | W18: =A18+U18 -> 46080 | X18: =if(A18>V18,"Late", "On time") -> On time | Y18: New Buy | AA18: Done | AB18: FATP-MP-4CS4-MVA2603-04OM | AC18: Done | AD18: 100x 1FSHQ30097 63x 1FSHQ30098 | AE18: Done | AF18: 100x 1FSHQ30097 63x 1FSHQ30098 | AG18: pending | AH18: =vlookup(AF18,Sheet9!A:D,3,0) | AI18: EPR2603070015 | AL18: =if(AA18="Done",$J18,0) -> 163 | AM18: =if(AC18="Done",$J18,0) -> 163 | AN18: =if(AE18="Done",$J18,0) -> 163 | AO18: =if(AH18<>"",$J18,0) -> 0
A19: 46080 | B19: MFG | C19: To Thi Phuong Anh | D19: V1524505 | E19: Phuong Anh To | G19: Barcode Scanner SEUIC HS505DP, USB cable | H19: =vlookup(G19,'Bidding list 26'!$B$4:$G$270,6,0) -> HS505DP, USB cable | I19: 2300000 | J19: 160 | K19: =I19*J19 -> 368000000 | L19: 4CS4 | M19: P26 | N19: 4CS4 | O19: FATP | P19: MP | Q19: 46123 | R19: =Q19-A19 -> 43 | S19: {=INDEX('G Project Timeline-OPM update'!$G$7:$L$35,MATCH(1,('G Project Timeline-OPM update'!$C$7:$C$35=N19)*('G Project Timeline-OPM update'!$B$7:$B$35=M19)*('G Project Timeline-OPM update'!$D$7:$D$35=O19),0),MATCH(P19,'G Project Timeline-OPM update'!$G$4:$L$4,0))-14} -> 46135 | T19: =S19-A19 -> 55 | U19: =IFERROR(VLOOKUP(G19,'Bidding list 26'!$B$2:$P$31,15,0),"") -> 50 | V19: =S19-U19 -> 46085 | W19: =A19+U19 -> 46130 | X19: =if(A19>V19,"Late", "On time") -> On time | Y19: New Buy | AA19: Done | AB19: FATP-MP-4CS4-MVA2603-29OM | AC19: Done | AD19: VNPR202604040091 | AE19: Done | AF19: VNPO202604160165 | AG19: 46171 | AH19: 46172 | AI19: EPR2603210010 | AL19: =if(AA19="Done",$J19,0) -> 160 | AM19: =if(AC19="Done",$J19,0) -> 160 | AN19: =if(AE19="Done",$J19,0) -> 160 | AO19: =if(AH19<>"",$J19,0) -> 160
A20: 46080 | B20: MFG | C20: To Thi Phuong Anh | D20: V1524505 | E20: Phuong Anh To | G20: Barcode Scanner SEUIC HS505HDP-2530 ,USB cable | H20: =vlookup(G20,'Bidding list 26'!$B$4:$G$270,6,0) -> SEUIC HS505HDP-2530 ,USB cable | I20: 3300000 | J20: 6 | K20: =I20*J20 -> 19800000 | L20: 4CS4 | M20: P26 | N20: 4CS4 | O20: FATP | P20: MP | Q20: 46123 | R20: =Q20-A20 -> 43 | S20: {=INDEX('G Project Timeline-OPM update'!$G$7:$L$35,MATCH(1,('G Project Timeline-OPM update'!$C$7:$C$35=N20)*('G Project Timeline-OPM update'!$B$7:$B$35=M20)*('G Project Timeline-OPM update'!$D$7:$D$35=O20),0),MATCH(P20,'G Project Timeline-OPM update'!$G$4:$L$4,0))-14} -> 46135 | T20: =S20-A20 -> 55 | U20: =IFERROR(VLOOKUP(G20,'Bidding list 26'!$B$2:$P$31,15,0),"") -> 50 | V20: =S20-U20 -> 46085 | W20: =A20+U20 -> 46130 | X20: =if(A20>V20,"Late", "On time") -> On time | Y20: New Buy | AA20: Done | AB20: FATP-MP-4CS4-MVA2603-29OM | AC20: Done | AD20: VNPR202604040091 | AE20: Done | AF20: VNPO202604160165 | AG20: Dự kiến 25/05 hàng về | AI20: EPR2603210011 | AL20: =if(AA20="Done",$J20,0) -> 6 | AM20: =if(AC20="Done",$J20,0) -> 6 | AN20: =if(AE20="Done",$J20,0) -> 6 | AO20: =if(AH20<>"",$J20,0) -> 0
A21: 46080 | B21: MFG | C21: To Thi Phuong Anh | D21: V1524505 | E21: Phuong Anh To | G21: Barcode Printer ZEBRA | H21: =vlookup(G21,'Bidding list 26'!$B$4:$G$270,6,0) -> ZT610, 600dpi | I21: 48800000 | J21: 20 | K21: =I21*J21 -> 976000000 | L21: 4CS4 | M21: P26 | N21: 4CS4 | O21: FATP | P21: MP | Q21: 46123 | R21: =Q21-A21 -> 43 | S21: {=INDEX('G Project Timeline-OPM update'!$G$7:$L$35,MATCH(1,('G Project Timeline-OPM update'!$C$7:$C$35=N21)*('G Project Timeline-OPM update'!$B$7:$B$35=M21)*('G Project Timeline-OPM update'!$D$7:$D$35=O21),0),MATCH(P21,'G Project Timeline-OPM update'!$G$4:$L$4,0))-14} -> 46135 | T21: =S21-A21 -> 55 | U21: =IFERROR(VLOOKUP(G21,'Bidding list 26'!$B$2:$P$31,15,0),"") -> 50 | V21: =S21-U21 -> 46085 | W21: =A21+U21 -> 46130 | X21: =if(A21>V21,"Late", "On time") -> On time | Y21: New Buy | AA21: Done | AB21: FATP-MP-4CS4-MVA2603-04OM | AC21: Done | AD21: 1FSHQ30099 | AE21: Done | AF21: 1FSHQ30099 | AH21: 46162 | AI21: EPR2603070016 | AL21: =if(AA21="Done",$J21,0) -> 20 | AM21: =if(AC21="Done",$J21,0) -> 20 | AN21: =if(AE21="Done",$J21,0) -> 20 | AO21: =if(AH21<>"",$J21,0) -> 20
A22: 46080 | B22: MFG | C22: To Thi Phuong Anh | D22: V1524505 | E22: Phuong Anh To | G22: Mini PC (Assy) | H22: =vlookup(G22,'Bidding list 26'!$B$4:$G$270,6,0) -> #N/A | I22: 7800000 | J22: 184 | K22: =I22*J22 -> 1435200000 | L22: CGY4 | M22: P26 | N22: CGY4 | O22: FATP | P22: MP | Q22: 46123 | R22: =Q22-A22 -> 43 | S22: {=INDEX('G Project Timeline-OPM update'!$G$7:$L$35,MATCH(1,('G Project Timeline-OPM update'!$C$7:$C$35=N22)*('G Project Timeline-OPM update'!$B$7:$B$35=M22)*('G Project Timeline-OPM update'!$D$7:$D$35=O22),0),MATCH(P22,'G Project Timeline-OPM update'!$G$4:$L$4,0))-14} -> 46135 | T22: =S22-A22 -> 55 | U22: =IFERROR(VLOOKUP(G22,'Bidding list 26'!$B$2:$P$31,15,0),"") | V22: =S22-U22 -> 46135 | W22: =A22+U22 -> 46080 | X22: =if(A22>V22,"Late", "On time") -> On time | Y22: New Buy | AA22: Done | AB22: FATP-MP-CGY4-MVA2603-05OM | AC22: Done | AD22: 100x 1FSHQ30103 84x 1FSHQ30108 | AE22: Done | AF22: 100x 1FSHQ30103 84x 1FSHQ30108 | AG22: pending | AH22: =vlookup(AF22,Sheet9!A:D,3,0) | AI22: EPR2603070018 | AK22: 120x mini PC (OR5) xuất urgent cho P26-CGY4 | AL22: =if(AA22="Done",$J22,0) -> 184 | AM22: =if(AC22="Done",$J22,0) -> 184 | AN22: =if(AE22="Done",$J22,0) -> 184 | AO22: =if(AH22<>"",$J22,0) -> 0
A23: 46080 | B23: MFG | C23: To Thi Phuong Anh | D23: V1524505 | E23: Phuong Anh To | G23: Monitor 2 | H23: =vlookup(G23,'Bidding list 26'!$B$4:$G$270,6,0) -> VA1903H-2, 19 inch, VGA cable + HDMI cable / Brand: VIEWSONIC | I23: 1240000 | J23: 35 | K23: =I23*J23 -> 43400000 | L23: CGY4 | M23: P26 | N23: CGY4 | O23: FATP | P23: MP | Q23: 46123 | R23: =Q23-A23 -> 43 | S23: {=INDEX('G Project Timeline-OPM update'!$G$7:$L$35,MATCH(1,('G Project Timeline-OPM update'!$C$7:$C$35=N23)*('G Project Timeline-OPM update'!$B$7:$B$35=M23)*('G Project Timeline-OPM update'!$D$7:$D$35=O23),0),MATCH(P23,'G Project Timeline-OPM update'!$G$4:$L$4,0))-14} -> 46135 | T23: =S23-A23 -> 55 | U23: =IFERROR(VLOOKUP(G23,'Bidding list 26'!$B$2:$P$31,15,0),"") -> 50 | V23: =S23-U23 -> 46085 | W23: =A23+U23 -> 46130 | X23: =if(A23>V23,"Late", "On time") -> On time | Y23: New Buy | AA23: Done | AB23: FATP-MP-CGY4-MVA2603-05OM | AC23: Done | AD23: 1FSHQ30102 | AE23: Done | AF23: 1FSHQ30102 | AG23: 46144 | AH23: 46144 | AI23: EPR2603070017 | AL23: =if(AA23="Done",$J23,0) -> 35 | AM23: =if(AC23="Done",$J23,0) -> 35 | AN23: =if(AE23="Done",$J23,0) -> 35 | AO23: =if(AH23<>"",$J23,0) -> 35
A24: 46080 | B24: MFG | C24: To Thi Phuong Anh | D24: V1524505 | E24: Phuong Anh To | G24: Barcode Scanner SEUIC HS505DP, USB cable | H24: =vlookup(G24,'Bidding list 26'!$B$4:$G$270,6,0) -> HS505DP, USB cable | I24: 2300000 | J24: 180 | K24: =I24*J24 -> 414000000 | L24: CGY4 | M24: P26 | N24: CGY4 | O24: FATP | P24: MP | Q24: 46123 | R24: =Q24-A24 -> 43 | S24: {=INDEX('G Project Timeline-OPM update'!$G$7:$L$35,MATCH(1,('G Project Timeline-OPM update'!$C$7:$C$35=N24)*('G Project Timeline-OPM update'!$B$7:$B$35=M24)*('G Project Timeline-OPM update'!$D$7:$D$35=O24),0),MATCH(P24,'G Project Timeline-OPM update'!$G$4:$L$4,0))-14} -> 46135 | T24: =S24-A24 -> 55 | U24: =IFERROR(VLOOKUP(G24,'Bidding list 26'!$B$2:$P$31,15,0),"") -> 50 | V24: =S24-U24 -> 46085 | W24: =A24+U24 -> 46130 | X24: =if(A24>V24,"Late", "On time") -> On time | Y24: New Buy | AA24: Done | AB24: FATP-MP-CGY4-MVA2603-30OM | AC24: Done | AD24: VNPR202604040108 | AE24: Done | AF24: VNPO202604160167 | AG24: 46171 | AH24: 46172 | AI24: EPR2603210012 | AL24: =if(AA24="Done",$J24,0) -> 180 | AM24: =if(AC24="Done",$J24,0) -> 180 | AN24: =if(AE24="Done",$J24,0) -> 180 | AO24: =if(AH24<>"",$J24,0) -> 180
A25: 46080 | B25: MFG | C25: To Thi Phuong Anh | D25: V1524505 | E25: Phuong Anh To | G25: Barcode Scanner SEUIC HS505HDP-2530 ,USB cable | H25: =vlookup(G25,'Bidding list 26'!$B$4:$G$270,6,0) -> SEUIC HS505HDP-2530 ,USB cable | I25: 3300000 | J25: 7 | K25: =I25*J25 -> 23100000 | L25: CGY4 | M25: P26 | N25: CGY4 | O25: FATP | P25: MP | Q25: 46123 | R25: =Q25-A25 -> 43 | S25: {=INDEX('G Project Timeline-OPM update'!$G$7:$L$35,MATCH(1,('G Project Timeline-OPM update'!$C$7:$C$35=N25)*('G Project Timeline-OPM update'!$B$7:$B$35=M25)*('G Project Timeline-OPM update'!$D$7:$D$35=O25),0),MATCH(P25,'G Project Timeline-OPM update'!$G$4:$L$4,0))-14} -> 46135 | T25: =S25-A25 -> 55 | U25: =IFERROR(VLOOKUP(G25,'Bidding list 26'!$B$2:$P$31,15,0),"") -> 50 | V25: =S25-U25 -> 46085 | W25: =A25+U25 -> 46130 | X25: =if(A25>V25,"Late", "On time") -> On time | Y25: New Buy | AA25: Done | AB25: FATP-MP-CGY4-MVA2603-30OM | AC25: Done | AD25: VNPR202604040108 | AE25: Done | AF25: VNPO202604160167 | AG25: 46193 | AH25: 46193 | AI25: EPR2603210013: Đã trả request trước PO | AL25: =if(AA25="Done",$J25,0) -> 7 | AM25: =if(AC25="Done",$J25,0) -> 7 | AN25: =if(AE25="Done",$J25,0) -> 7 | AO25: =if(AH25<>"",$J25,0) -> 7
A26: 46080 | B26: MFG | C26: To Thi Phuong Anh | D26: V1524505 | E26: Phuong Anh To | G26: Barcode Printer ZEBRA | H26: =vlookup(G26,'Bidding list 26'!$B$4:$G$270,6,0) -> ZT610, 600dpi | I26: 48800000 | J26: 31 | K26: =I26*J26 -> 1512800000 | L26: CGY4 | M26: P26 | N26: CGY4 | O26: FATP | P26: MP | Q26: 46123 | R26: =Q26-A26 -> 43 | S26: {=INDEX('G Project Timeline-OPM update'!$G$7:$L$35,MATCH(1,('G Project Timeline-OPM update'!$C$7:$C$35=N26)*('G Project Timeline-OPM update'!$B$7:$B$35=M26)*('G Project Timeline-OPM update'!$D$7:$D$35=O26),0),MATCH(P26,'G Project Timeline-OPM update'!$G$4:$L$4,0))-14} -> 46135 | T26: =S26-A26 -> 55 | U26: =IFERROR(VLOOKUP(G26,'Bidding list 26'!$B$2:$P$31,15,0),"") -> 50 | V26: =S26-U26 -> 46085 | W26: =A26+U26 -> 46130 | X26: =if(A26>V26,"Late", "On time") -> On time | Y26: New Buy | AA26: Done | AB26: FATP-MP-CGY4-MVA2603-05OM | AC26: Done | AD26: 20x 1FSHQ30106 11x 1FSHQ30107 | AE26: Done | AF26: 20x 1FSHQ30106 11x 1FSHQ30107 | AG26: 11x 1FSHQ30107 / 20/05 hàng về | AH26: =vlookup(AF26,Sheet9!A:D,3,0) | AI26: EPR2603070019 | AL26: =if(AA26="Done",$J26,0) -> 31 | AM26: =if(AC26="Done",$J26,0) -> 31 | AN26: =if(AE26="Done",$J26,0) -> 31 | AO26: =if(AH26<>"",$J26,0) -> 0
A27: 46080 | B27: MFG | C27: To Thi Phuong Anh | D27: V1524505 | E27: Phuong Anh To | G27: Monitor (White)+ ARM | H27: =vlookup(G27,'Bidding list 26'!$B$4:$G$270,6,0) -> HKC MB24V7-W, 23.8 inch White, With Bracket Arm Warrior WA-MH0802 (White) | I27: 1815000 | J27: 149 | K27: =I27*J27 -> 270435000 | L27: CGY4 | M27: P26 | N27: CGY4 | O27: FATP | P27: MP | Q27: 46123 | R27: =Q27-A27 -> 43 | S27: {=INDEX('G Project Timeline-OPM update'!$G$7:$L$35,MATCH(1,('G Project Timeline-OPM update'!$C$7:$C$35=N27)*('G Project Timeline-OPM update'!$B$7:$B$35=M27)*('G Project Timeline-OPM update'!$D$7:$D$35=O27),0),MATCH(P27,'G Project Timeline-OPM update'!$G$4:$L$4,0))-14} -> 46135 | T27: =S27-A27 -> 55 | U27: =IFERROR(VLOOKUP(G27,'Bidding list 26'!$B$2:$P$31,15,0),"") -> 80 | V27: =S27-U27 -> 46055 | W27: =A27+U27 -> 46160 | X27: =if(A27>V27,"Late", "On time") -> Late | Y27: New Buy | AA27: Done | AB27: FATP-MP-CGY4-MVA2603-05OM | AC27: Done | AD27: 1FSHQ30105 | AE27: Done | AF27: 1FSHQ30105 | AH27: =vlookup(AF27,Sheet9!A:D,3,0) -> Đã nhận 20.04 | AI27: EPR2603070020 | AL27: =if(AA27="Done",$J27,0) -> 149 | AM27: =if(AC27="Done",$J27,0) -> 149 | AN27: =if(AE27="Done",$J27,0) -> 149 | AO27: =if(AH27<>"",$J27,0) -> 149
A28: 46087 | B28: TE FATP | C28: Nguyen Trung Kien | D28: V1524574 | E28: kiennt1@fih-foxconn.com | F28: 4440 | G28: IPC++(updated) | H28: =vlookup(G28,'Bidding list 26'!$B$4:$G$270,6,0) -> Pro Tower QCT1250, Ultra 7 265, Ram 16GB DDR5, SSD 512GB, Integrated graphics card, Power 180W, HDMI & DP Port, Keyboard and Mouse, 3Yrs Wty | I28: 26752000 | J28: 76 | K28: =I28*J28 -> 2033152000 | L28: CGY4 FATP | M28: P26 Demo Line | N28: CGY4 | O28: FATP | P28: EVT | Q28: 46097 | R28: =Q28-A28 -> 10 | S28: {=INDEX('G Project Timeline-OPM update'!$G$7:$L$35,MATCH(1,('G Project Timeline-OPM update'!$C$7:$C$35=N28)*('G Project Timeline-OPM update'!$B$7:$B$35=M28)*('G Project Timeline-OPM update'!$D$7:$D$35=O28),0),MATCH(P28,'G Project Timeline-OPM update'!$G$4:$L$4,0))-14} -> 46058 | T28: =S28-A28 -> -29 | U28: =IFERROR(VLOOKUP(G28,'Bidding list 26'!$B$2:$P$31,15,0),"") -> 70 | V28: =S28-U28 -> 45988 | W28: =A28+U28 -> 46157 | X28: =if(A28>V28,"Late", "On time") -> Late | Y28: New Buy | AA28: Done | AB28: FATP-MP-P26-MVA2603-01OM | AC28: Done | AD28: 40x 1FSHQ30073 40x 1FSHQ30075 40x 1FSHQ30076 21x 1FSHQ30078 | AE28: Done | AF28: 40x 1FSHQ30073 40x 1FSHQ30075 40x 1FSHQ30076 21x 1FSHQ30078 | AH28: 46126 | AI28: EPR2603210043 ( Số lượng QTY cụ thể đã chia trên file chị Q) | AL28: =if(AA28="Done",$J28,0) -> 76 | AM28: =if(AC28="Done",$J28,0) -> 76 | AN28: =if(AE28="Done",$J28,0) -> 76 | AO28: =if(AH28<>"",$J28,0) -> 76
A29: 46087 | B29: TE SMT | C29: Nguyen Trung Kien | D29: V1524574 | E29: kiennt1@fih-foxconn.com | F29: 4440 | G29: IPC++(updated) | H29: =vlookup(G29,'Bidding list 26'!$B$4:$G$270,6,0) -> Pro Tower QCT1250, Ultra 7 265, Ram 16GB DDR5, SSD 512GB, Integrated graphics card, Power 180W, HDMI & DP Port, Keyboard and Mouse, 3Yrs Wty | I29: 26752000 | J29: 36 | K29: =I29*J29 -> 963072000 | L29: CGY4 SMT | M29: P26 Demo Line | N29: CGY4 | O29: SMT | P29: EVT | Q29: 46097 | R29: =Q29-A29 -> 10 | S29: {=INDEX('G Project Timeline-OPM update'!$G$7:$L$35,MATCH(1,('G Project Timeline-OPM update'!$C$7:$C$35=N29)*('G Project Timeline-OPM update'!$B$7:$B$35=M29)*('G Project Timeline-OPM update'!$D$7:$D$35=O29),0),MATCH(P29,'G Project Timeline-OPM update'!$G$4:$L$4,0))-14} -> 46058 | T29: =S29-A29 -> -29 | U29: =IFERROR(VLOOKUP(G29,'Bidding list 26'!$B$2:$P$31,15,0),"") -> 70 | V29: =S29-U29 -> 45988 | W29: =A29+U29 -> 46157 | X29: =if(A29>V29,"Late", "On time") -> Late | Y29: New Buy | AA29: Done | AB29: SMT-MP-P26-MVA2603-17OM | AC29: Done | AD29: 1FSHQ30200 | AE29: Done | AF29: 1FSHQ30200 | AH29: 46126 | AI29: EPR2603210044 | AL29: =if(AA29="Done",$J29,0) -> 36 | AM29: =if(AC29="Done",$J29,0) -> 36 | AN29: =if(AE29="Done",$J29,0) -> 36 | AO29: =if(AH29<>"",$J29,0) -> 36
A30: 46087 | B30: TE FATP | C30: Nguyen Trung Kien | D30: V1524574 | E30: kiennt1@fih-foxconn.com | F30: 4440 | G30: IPC++(updated) | H30: =vlookup(G30,'Bidding list 26'!$B$4:$G$270,6,0) -> Pro Tower QCT1250, Ultra 7 265, Ram 16GB DDR5, SSD 512GB, Integrated graphics card, Power 180W, HDMI & DP Port, Keyboard and Mouse, 3Yrs Wty | I30: 26752000 | J30: 65 | K30: =I30*J30 -> 1738880000 | L30: 4CS4 FATP | M30: P26 | N30: 4CS4 | O30: FATP | P30: MP | Q30: 46097 | R30: =Q30-A30 -> 10 | S30: {=INDEX('G Project Timeline-OPM update'!$G$7:$L$35,MATCH(1,('G Project Timeline-OPM update'!$C$7:$C$35=N30)*('G Project Timeline-OPM update'!$B$7:$B$35=M30)*('G Project Timeline-OPM update'!$D$7:$D$35=O30),0),MATCH(P30,'G Project Timeline-OPM update'!$G$4:$L$4,0))-14} -> 46135 | T30: =S30-A30 -> 48 | U30: =IFERROR(VLOOKUP(G30,'Bidding list 26'!$B$2:$P$31,15,0),"") -> 70 | V30: =S30-U30 -> 46065 | W30: =A30+U30 -> 46157 | X30: =if(A30>V30,"Late", "On time") -> Late | Y30: New Buy | AA30: Done | AB30: FATP-MP-P26-MVA2603-01OM | AC30: Done | AD30: 40x 1FSHQ30073 40x 1FSHQ30075 40x 1FSHQ30076 21x 1FSHQ30078 | AE30: Done | AF30: 40x 1FSHQ30073 40x 1FSHQ30075 40x 1FSHQ30076 21x 1FSHQ30078 | AH30: 46126 | AI30: EPR2603210045 ( Số lượng QTY cụ thể đã chia trên file chị Q) | AL30: =if(AA30="Done",$J30,0) -> 65 | AM30: =if(AC30="Done",$J30,0) -> 65 | AN30: =if(AE30="Done",$J30,0) -> 65 | AO30: =if(AH30<>"",$J30,0) -> 65
A31: 46087 | B31: TE SMT | C31: Nguyen Trung Kien | D31: V1524574 | E31: kiennt1@fih-foxconn.com | F31: 4440 | G31: IPC++(updated) | H31: =vlookup(G31,'Bidding list 26'!$B$4:$G$270,6,0) -> Pro Tower QCT1250, Ultra 7 265, Ram 16GB DDR5, SSD 512GB, Integrated graphics card, Power 180W, HDMI & DP Port, Keyboard and Mouse, 3Yrs Wty | I31: 26752000 | J31: 38 | K31: =I31*J31 -> 1016576000 | L31: 4CS4 SMT | M31: P26 | N31: 4CS4 | O31: SMT | P31: MP | Q31: 46097 | R31: =Q31-A31 -> 10 | S31: {=INDEX('G Project Timeline-OPM update'!$G$7:$L$35,MATCH(1,('G Project Timeline-OPM update'!$C$7:$C$35=N31)*('G Project Timeline-OPM update'!$B$7:$B$35=M31)*('G Project Timeline-OPM update'!$D$7:$D$35=O31),0),MATCH(P31,'G Project Timeline-OPM update'!$G$4:$L$4,0))-14} -> 46135 | T31: =S31-A31 -> 48 | U31: =IFERROR(VLOOKUP(G31,'Bidding list 26'!$B$2:$P$31,15,0),"") -> 70 | V31: =S31-U31 -> 46065 | W31: =A31+U31 -> 46157 | X31: =if(A31>V31,"Late", "On time") -> Late | Y31: New Buy | AA31: Done | AB31: SMT-MP-P26-MVA2603-17OM | AC31: Done | AD31: 1FSHQ30201 | AE31: Done | AF31: 1FSHQ30201 | AH31: 46126 | AI31: EPR2603210046 | AL31: =if(AA31="Done",$J31,0) -> 38 | AM31: =if(AC31="Done",$J31,0) -> 38 | AN31: =if(AE31="Done",$J31,0) -> 38 | AO31: =if(AH31<>"",$J31,0) -> 38
A32: 46094 | B32: GG-WH | C32: Nguyen Thi Viet | D32: V1524536 | E32: Vietnt@fih-foxconn.com | F32: 4478 | G32: Monitor 1 | H32: =vlookup(G32,'Bidding list 26'!$B$4:$G$270,6,0) -> DELL E2225HM, 21.5 inch HDMI cable, 3Yrs Wty | I32: 1980000 | J32: 3 | K32: =I32*J32 -> 5940000 | L32: 4CS4 SVR line | M32: P26 Service line | N32: 4CS4 | O32: FATP | P32: MP | Q32: 46127 | R32: =Q32-A32 -> 33 | S32: {=INDEX('G Project Timeline-OPM update'!$G$7:$L$35,MATCH(1,('G Project Timeline-OPM update'!$C$7:$C$35=N32)*('G Project Timeline-OPM update'!$B$7:$B$35=M32)*('G Project Timeline-OPM update'!$D$7:$D$35=O32),0),MATCH(P32,'G Project Timeline-OPM update'!$G$4:$L$4,0))-14} -> 46146 | T32: =S32-A32 -> 52 | U32: =IFERROR(VLOOKUP(G32,'Bidding list 26'!$B$2:$P$31,15,0),"") -> 50 | V32: =S32-U32 -> 46096 | W32: =A32+U32 -> 46144 | X32: =if(A32>V32,"Late", "On time") -> On time | Y32: New Buy | Z32: G | AA32: Done | AB32: FATP-SV-4CS4-MVA2603-42OM | AC32: Done | AD32: 1FSHQ40058 | AE32: Done | AF32: 1FSHQ40058 | AG32: =vlookup(AF32,Sheet9!A:D,4,0) | AH32: 46141 | AI32: EPR2603240015 | AL32: =if(AA32="Done",$J32,0) -> 3 | AM32: =if(AC32="Done",$J32,0) -> 3 | AN32: =if(AE32="Done",$J32,0) -> 3 | AO32: =if(AH32<>"",$J32,0) -> 3
A33: 46094 | B33: GG-WH | C33: Nguyen Thi Viet | D33: V1524536 | E33: Vietnt@fih-foxconn.com | F33: 4478 | G33: IPC+(updated) | H33: =vlookup(G33,'Bidding list 26'!$B$4:$G$270,6,0) -> Pro Tower QCT1250, Ultra 5 235, Ram 16GB DDR5, SSD 512GB, Integrated graphics card, Power 180W, HDMI & DP Port, Keyboard and Mouse, 3Yrs Wty | I33: 18717000 | J33: 3 | K33: =I33*J33 -> 56151000 | L33: 4CS4 SVR line | M33: P26 Service line | N33: 4CS4 | O33: FATP | P33: MP | Q33: 46127 | R33: =Q33-A33 -> 33 | S33: {=INDEX('G Project Timeline-OPM update'!$G$7:$L$35,MATCH(1,('G Project Timeline-OPM update'!$C$7:$C$35=N33)*('G Project Timeline-OPM update'!$B$7:$B$35=M33)*('G Project Timeline-OPM update'!$D$7:$D$35=O33),0),MATCH(P33,'G Project Timeline-OPM update'!$G$4:$L$4,0))-14} -> 46146 | T33: =S33-A33 -> 52 | U33: =IFERROR(VLOOKUP(G33,'Bidding list 26'!$B$2:$P$31,15,0),"") -> 70 | V33: =S33-U33 -> 46076 | W33: =A33+U33 -> 46164 | X33: =if(A33>V33,"Late", "On time") -> Late | Y33: New Buy | Z33: G | AA33: Done | AB33: FATP-SV-4CS4-MVA2603-42OM | AC33: Done | AD33: 1FSHQ40057 | AF33: 1FSHQ40057 | AH33: Đã nhận 23/04 | AI33: EPR2603240016 | AL33: =if(AA33="Done",$J33,0) -> 3 | AM33: =if(AC33="Done",$J33,0) -> 3 | AN33: =if(AE33="Done",$J33,0) -> 0 | AO33: =if(AH33<>"",$J33,0) -> 3
A34: 46094 | B34: GG-WH | C34: Nguyen Thi Viet | D34: V1524536 | E34: Vietnt@fih-foxconn.com | F34: 4478 | G34: PDA CHAINWAY C61-4850 | H34: =vlookup(G34,'Bidding list 26'!$B$4:$G$270,6,0) -> C61-4850, Not including RFID module. Includes: 64GB 27-key Android 11, controller with battery, charging dock, charging adapter, glass screen protector | I34: 15500000 | J34: 1 | K34: =I34*J34 -> 15500000 | L34: 4CS4 SVR line | M34: P26 | N34: 4CS4 | O34: FATP | P34: MP | Q34: 46127 | R34: =Q34-A34 -> 33 | S34: {=INDEX('G Project Timeline-OPM update'!$G$7:$L$35,MATCH(1,('G Project Timeline-OPM update'!$C$7:$C$35=N34)*('G Project Timeline-OPM update'!$B$7:$B$35=M34)*('G Project Timeline-OPM update'!$D$7:$D$35=O34),0),MATCH(P34,'G Project Timeline-OPM update'!$G$4:$L$4,0))-14} -> 46135 | T34: =S34-A34 -> 41 | U34: =IFERROR(VLOOKUP(G34,'Bidding list 26'!$B$2:$P$31,15,0),"") -> 65 | V34: =S34-U34 -> 46070 | W34: =A34+U34 -> 46159 | X34: =if(A34>V34,"Late", "On time") -> Late | Y34: New Buy | Z34: G | AA34: Done | AB34: FATP-MP-4CS4-MVA2603-42OM | AC34: Done | AD34: VNPR202603260169 | AE34: Done | AF34: VNPO202603310112 | AH34: 46149 | AI34: EPR2603240017 | AK34: đã out 20may tại vp OM - chị Việt | AL34: =if(AA34="Done",$J34,0) -> 1 | AM34: =if(AC34="Done",$J34,0) -> 1 | AN34: =if(AE34="Done",$J34,0) -> 1 | AO34: =if(AH34<>"",$J34,0) -> 1
A35: 46094 | B35: GG-WH | C35: Nguyen Thi Viet | D35: V1524536 | E35: Vietnt@fih-foxconn.com | F35: 4478 | G35: Barcode Scanner ZEBRA DS8178,USB cable | H35: =vlookup(G35,'Bidding list 26'!$B$4:$G$270,6,0) -> ZEBRA DS8178,USB cable PCS Wireless Scanner | I35: 5800000 | J35: 1 | K35: =I35*J35 -> 5800000 | L35: 4CS4 SVR line | M35: P26 | N35: 4CS4 | O35: FATP | P35: MP | Q35: 46127 | R35: =Q35-A35 -> 33 | S35: {=INDEX('G Project Timeline-OPM update'!$G$7:$L$35,MATCH(1,('G Project Timeline-OPM update'!$C$7:$C$35=N35)*('G Project Timeline-OPM update'!$B$7:$B$35=M35)*('G Project Timeline-OPM update'!$D$7:$D$35=O35),0),MATCH(P35,'G Project Timeline-OPM update'!$G$4:$L$4,0))-14} -> 46135 | T35: =S35-A35 -> 41 | U35: =IFERROR(VLOOKUP(G35,'Bidding list 26'!$B$2:$P$31,15,0),"") -> 65 | V35: =S35-U35 -> 46070 | W35: =A35+U35 -> 46159 | X35: =if(A35>V35,"Late", "On time") -> Late | Y35: New Buy | Z35: G | AA35: Done | AB35: FATP-MP-4CS4-MVA2603-42OM | AC35: Done | AD35: VNPR202603260169 | AE35: Done | AF35: VNPO202603310112 | AH35: Đã nhận 25.04 | AI35: EPR2603210023 | AL35: =if(AA35="Done",$J35,0) -> 1 | AM35: =if(AC35="Done",$J35,0) -> 1 | AN35: =if(AE35="Done",$J35,0) -> 1 | AO35: =if(AH35<>"",$J35,0) -> 1
A36: 46094 | B36: GG-WH | C36: Nguyen Thi Viet | D36: V1524536 | E36: Vietnt@fih-foxconn.com | F36: 4478 | G36: Monitor 1 | H36: =vlookup(G36,'Bidding list 26'!$B$4:$G$270,6,0) -> DELL E2225HM, 21.5 inch HDMI cable, 3Yrs Wty | I36: 1980000 | J36: 3 | K36: =I36*J36 -> 5940000 | L36: CGY4 SVR line | M36: P26 Service line | N36: CGY4 | O36: FATP | P36: MP | Q36: 46127 | R36: =Q36-A36 -> 33 | S36: {=INDEX('G Project Timeline-OPM update'!$G$7:$L$35,MATCH(1,('G Project Timeline-OPM update'!$C$7:$C$35=N36)*('G Project Timeline-OPM update'!$B$7:$B$35=M36)*('G Project Timeline-OPM update'!$D$7:$D$35=O36),0),MATCH(P36,'G Project Timeline-OPM update'!$G$4:$L$4,0))-14} -> 46146 | T36: =S36-A36 -> 52 | U36: =IFERROR(VLOOKUP(G36,'Bidding list 26'!$B$2:$P$31,15,0),"") -> 50 | V36: =S36-U36 -> 46096 | W36: =A36+U36 -> 46144 | X36: =if(A36>V36,"Late", "On time") -> On time | Y36: New Buy | Z36: G | AA36: Done | AB36: FATP-SV-CGY4-MVA2603-43OM | AC36: Done | AD36: 1FSHQ40061 | AE36: Done | AF36: 1FSHQ40061 | AH36: 46141 | AI36: EPR2603240018 | AL36: =if(AA36="Done",$J36,0) -> 3 | AM36: =if(AC36="Done",$J36,0) -> 3 | AN36: =if(AE36="Done",$J36,0) -> 3 | AO36: =if(AH36<>"",$J36,0) -> 3
A37: 46094 | B37: GG-WH | C37: Nguyen Thi Viet | D37: V1524536 | E37: Vietnt@fih-foxconn.com | F37: 4478 | G37: IPC+(updated) | H37: =vlookup(G37,'Bidding list 26'!$B$4:$G$270,6,0) -> Pro Tower QCT1250, Ultra 5 235, Ram 16GB DDR5, SSD 512GB, Integrated graphics card, Power 180W, HDMI & DP Port, Keyboard and Mouse, 3Yrs Wty | I37: 18717000 | J37: 3 | K37: =I37*J37 -> 56151000 | L37: CGY4 SVR line | M37: P26 Service line | N37: CGY4 | O37: FATP | P37: MP | Q37: 46127 | R37: =Q37-A37 -> 33 | S37: {=INDEX('G Project Timeline-OPM update'!$G$7:$L$35,MATCH(1,('G Project Timeline-OPM update'!$C$7:$C$35=N37)*('G Project Timeline-OPM update'!$B$7:$B$35=M37)*('G Project Timeline-OPM update'!$D$7:$D$35=O37),0),MATCH(P37,'G Project Timeline-OPM update'!$G$4:$L$4,0))-14} -> 46146 | T37: =S37-A37 -> 52 | U37: =IFERROR(VLOOKUP(G37,'Bidding list 26'!$B$2:$P$31,15,0),"") -> 70 | V37: =S37-U37 -> 46076 | W37: =A37+U37 -> 46164 | X37: =if(A37>V37,"Late", "On time") -> Late | Y37: New Buy | Z37: G | AA37: Done | AB37: FATP-SV-CGY4-MVA2603-43OM | AC37: Done | AD37: 1FSHQ40059 | AE37: Done | AF37: 1FSHQ40059 | AH37: Đã nhận | AI37: EPR2603240019 | AL37: =if(AA37="Done",$J37,0) -> 3 | AM37: =if(AC37="Done",$J37,0) -> 3 | AN37: =if(AE37="Done",$J37,0) -> 3 | AO37: =if(AH37<>"",$J37,0) -> 3
A38: 46094 | B38: GG-WH | C38: Nguyen Thi Viet | D38: V1524536 | E38: Vietnt@fih-foxconn.com | F38: 4478 | G38: PDA CHAINWAY C61-4850 | H38: =vlookup(G38,'Bidding list 26'!$B$4:$G$270,6,0) -> C61-4850, Not including RFID module. Includes: 64GB 27-key Android 11, controller with battery, charging dock, charging adapter, glass screen protector | I38: 15500000 | J38: 1 | K38: =I38*J38 -> 15500000 | L38: CGY4 SVR line | M38: P26 | N38: CGY4 | O38: FATP | P38: MP | Q38: 46127 | R38: =Q38-A38 -> 33 | S38: {=INDEX('G Project Timeline-OPM update'!$G$7:$L$35,MATCH(1,('G Project Timeline-OPM update'!$C$7:$C$35=N38)*('G Project Timeline-OPM update'!$B$7:$B$35=M38)*('G Project Timeline-OPM update'!$D$7:$D$35=O38),0),MATCH(P38,'G Project Timeline-OPM update'!$G$4:$L$4,0))-14} -> 46135 | T38: =S38-A38 -> 41 | U38: =IFERROR(VLOOKUP(G38,'Bidding list 26'!$B$2:$P$31,15,0),"") -> 65 | V38: =S38-U38 -> 46070 | W38: =A38+U38 -> 46159 | X38: =if(A38>V38,"Late", "On time") -> Late | Y38: New Buy | Z38: G | AA38: Done | AB38: FATP-MP-CGY4-MVA2603-43OM | AC38: Done | AD38: VNPR202603260195 | AE38: Done | AF38: VNPO202603310112 | AH38: 46149 | AI38: EPR2603240020 | AK38: đã out 20may tại vp OM - chị Việt | AL38: =if(AA38="Done",$J38,0) -> 1 | AM38: =if(AC38="Done",$J38,0) -> 1 | AN38: =if(AE38="Done",$J38,0) -> 1 | AO38: =if(AH38<>"",$J38,0) -> 1
A39: 46094 | B39: GG-WH | C39: Nguyen Thi Viet | D39: V1524536 | E39: Vietnt@fih-foxconn.com | F39: 4478 | G39: Barcode Scanner ZEBRA DS8178,USB cable | H39: =vlookup(G39,'Bidding list 26'!$B$4:$G$270,6,0) -> ZEBRA DS8178,USB cable PCS Wireless Scanner | I39: 5800000 | J39: 1 | K39: =I39*J39 -> 5800000 | L39: CGY4 SVR line | M39: P26 | N39: CGY4 | O39: FATP | P39: MP | Q39: 46127 | R39: =Q39-A39 -> 33 | S39: {=INDEX('G Project Timeline-OPM update'!$G$7:$L$35,MATCH(1,('G Project Timeline-OPM update'!$C$7:$C$35=N39)*('G Project Timeline-OPM update'!$B$7:$B$35=M39)*('G Project Timeline-OPM update'!$D$7:$D$35=O39),0),MATCH(P39,'G Project Timeline-OPM update'!$G$4:$L$4,0))-14} -> 46135 | T39: =S39-A39 -> 41 | U39: =IFERROR(VLOOKUP(G39,'Bidding list 26'!$B$2:$P$31,15,0),"") -> 65 | V39: =S39-U39 -> 46070 | W39: =A39+U39 -> 46159 | X39: =if(A39>V39,"Late", "On time") -> Late | Y39: New Buy | Z39: G | AA39: Done | AB39: FATP-MP-CGY4-MVA2603-43OM | AC39: Done | AD39: VNPR202603260195 | AE39: Done | AF39: VNPO202603310112 | AH39: Đã nhận 25.04 | AI39: EPR2603210025 | AL39: =if(AA39="Done",$J39,0) -> 1 | AM39: =if(AC39="Done",$J39,0) -> 1 | AN39: =if(AE39="Done",$J39,0) -> 1 | AO39: =if(AH39<>"",$J39,0) -> 1
A40: 46094 | B40: GG-WH | C40: Nguyen Thi Viet | D40: V1524536 | E40: Vietnt@fih-foxconn.com | F40: 4478 | G40: Monitor 1 | H40: =vlookup(G40,'Bidding list 26'!$B$4:$G$270,6,0) -> DELL E2225HM, 21.5 inch HDMI cable, 3Yrs Wty | I40: 1980000 | J40: 3 | K40: =I40*J40 -> 5940000 | L40: PKK4 SVR line | M40: P26 Service line | N40: PKK4 | O40: FATP | P40: MP | Q40: 46127 | R40: =Q40-A40 -> 33 | S40: {=INDEX('G Project Timeline-OPM update'!$G$7:$L$35,MATCH(1,('G Project Timeline-OPM update'!$C$7:$C$35=N40)*('G Project Timeline-OPM update'!$B$7:$B$35=M40)*('G Project Timeline-OPM update'!$D$7:$D$35=O40),0),MATCH(P40,'G Project Timeline-OPM update'!$G$4:$L$4,0))-14} -> 46146 | T40: =S40-A40 -> 52 | U40: =IFERROR(VLOOKUP(G40,'Bidding list 26'!$B$2:$P$31,15,0),"") -> 50 | V40: =S40-U40 -> 46096 | W40: =A40+U40 -> 46144 | X40: =if(A40>V40,"Late", "On time") -> On time | Y40: New Buy | Z40: G | AA40: Done | AB40: FATP-SV-PKK4-MVA2603-44OM | AC40: Done | AD40: 1FSHQ40063 | AE40: Done | AF40: 1FSHQ40063 | AH40: 46141 | AI40: EPR2603240021 | AL40: =if(AA40="Done",$J40,0) -> 3 | AM40: =if(AC40="Done",$J40,0) -> 3 | AN40: =if(AE40="Done",$J40,0) -> 3 | AO40: =if(AH40<>"",$J40,0) -> 3
...

Sheet Check mini PC issue
A2: Mini PC Lamitouch Issue
A3: Project | B3: Dept | C3: Qty request | D3: Yubo Supplied Qty | E3: Pending Qty | F3: PO release Qty | G3: Actual Backup | H3: Detail back up | I3: Pending Supply Qty
A4: P26 MP | B4: MFG | C4: 378 | D4: 0 | E4: =C4-D4 -> 378 | F4: 378 | G4: =92+40+120+5+7+12-14 -> 262 | H4: +12x-newbuy from P26 zombie line -DL return: +40x- PC Assy at OM WH +120x - newbuy from OR5 - DL return: -14x-NG line return +5x- borrow OR5 wisetech-DL return: +7x-OM stock-lev for P26 +8x PC Assy (8x MFG return NG, OM check OK- re-supplied) +4x PC Assy-borrow PQE-DL return: | I4: =C4-G4 -> 116
B5: ENG | C5: 24 | D5: 0 | E5: =C5-D5 -> 24 | F5: 24 | G5: 0 | I5: =C5-G5 -> 24 | J5: Cancel PO, change to order from Banico Mini PC Asus
A6: P26 service | B6: MFG | C6: 121 | D6: 0 | E6: =C6-D6 -> 121 | F6: =121-48 -> 73 | G6: 80 | H6: Đang mượn 80x from p26 zombie line-DL ruturn: | I6: =C6-G6 -> 41
B7: ENG | C7: 3 | D7: 0 | E7: 3 | F7: 0 | G7: 0 | I7: =C7-G7 -> 3
A8: P27 P1.0 | B8: MFG | C8: 140 | D8: 0 | E8: =C8-D8 -> 140 | F8: 0 | G8: 140 | H8: Order 140x- Mini PC asus Banico- Received | I8: =C8-G8 -> 0
A9: Total | C9: =SUM(C4:C8) -> 666 | D9: =SUM(D4:D8) -> 0 | E9: =SUM(E4:E8) -> 666 | F9: =SUM(F4:F8) -> 475 | G9: =SUM(G4:G8) -> 482 | I9: =C9-G9 -> 184
F10: Cancel 475x, change order to NUC asus Banico | I10: 92 | J10: Trả P26 zombie line
F11: Remain Qty not yet released PO | G11: =804-475 -> 329 | I11: =SUM(I9:I10) -> 276
A14: now Total order request mini Lamitouch 780x for P26-378x, P26 service: 124x (Line open date 5/18), P27: 278x ( line open date 6/1). Current we temporary use pending pickup mini PC of P26 zombie line 92x and PC assy 40x supplied for P26 MP, total Qty lack ~ 780x-132x= 648x

Sheet NON G MVA EQ request
A1: Date of Request | B1: Department | C1: Requester name | D1: Requester employee ID | E1: Email | F1: Phone | G1: Item | H1: Request equipment spec | I1: Price | J1: Quantity | K1: Total Cost | L1: Purpose | M1: Year Project | N1: Project | O1: Phase | P1: Stage | Q1: Required Delivery Date (update by DRI) | R1: Given LT (days) (follow DRI update) | S1: Required Delivery Date follow Stage date (line open date - 14 days) | T1: Given LT (days) follow stage date | U1: Total Leadtime | V1: Request Deadline | W1: Late/ ontime | X1: Action | Y1: Remark | Z1: Budget Status | AA1: Budget # | AB1: PR Status | AC1: PR # | AD1: PO Status | AE1: PO # | AF1: ETA (Plan) | AG1: DTA (Actual) | AH1: #PUR request No | AI1: Action for delivery later than time Setup line | AK1: Qty Done Budget | AL1: Qty Done PQ | AM1: Qty Done PO | AN1: Qty Recieved
A2: 46035 | B2: FAE | C2: Vu Xuan Bach | D2: V1521896 | E2: bachvx@fih-foxconn.com | F2: 3546/3435 | G2: IPC | H2: =vlookup(G2,'Bidding list 26'!$B$4:$G$270,6,0) -> #N/A | I2: 10870000 | J2: 2 | K2: =I2*J2 -> 21740000 | L2: OR6 EVT | N2: OR6 | O2: FATP | P2: EVT | Q2: 46052 | R2: =Q2-A2 -> 17 | S2: {=INDEX('NONG Project Timeline-OPM updat'!$D$8:$I$65,MATCH(1,('NONG Project Timeline-OPM updat'!$B$8:$B$65=N2)*('NONG Project Timeline-OPM updat'!$C$8:$C$65=O2),0),MATCH(P2,'NONG Project Timeline-OPM updat'!$D$5:$I$5,0))-14} -> 46074 | T2: =S2-A2 -> 39 | U2: =IFERROR(VLOOKUP(G2,'Bidding list 26'!$B$2:$P$21,15,0),"") | V2: =S2-U2 -> 46074 | W2: =if(A2>V2,"Late", "On time") -> On time | X2: New Buy | Z2: Done | AB2: Done | AD2: Done | AG2: 46073 | AH2: EPR2602020005 : Done | AJ2: =B2&G2&J2&N2&X2&AA2 -> FAEIPC2OR6New Buy | AK2: =if(Z2="Done",$J2,0) -> 2 | AL2: =if(AB2="Done",$J2,0) -> 2 | AM2: =if(AD2="Done",$J2,0) -> 2 | AN2: =if(AG2<>"",$J2,0) -> 2
A3: 46035 | B3: FAE | C3: Vu Xuan Bach | D3: V1521896 | E3: bachvx@fih-foxconn.com | G3: Monitor 1 | H3: =vlookup(G3,'Bidding list 26'!$B$4:$G$270,6,0) -> DELL E2225HM, 21.5 inch HDMI cable, 3Yrs Wty | I3: 1980000 | J3: 2 | K3: =I3*J3 -> 3960000 | L3: OR6 EVT | N3: OR6 | O3: FATP | P3: EVT | Q3: 46052 | R3: =Q3-A3 -> 17 | S3: {=INDEX('NONG Project Timeline-OPM updat'!$D$8:$I$65,MATCH(1,('NONG Project Timeline-OPM updat'!$B$8:$B$65=N3)*('NONG Project Timeline-OPM updat'!$C$8:$C$65=O3),0),MATCH(P3,'NONG Project Timeline-OPM updat'!$D$5:$I$5,0))-14} -> 46074 | T3: =S3-A3 -> 39 | U3: =IFERROR(VLOOKUP(G3,'Bidding list 26'!$B$2:$P$21,15,0),"") | V3: =S3-U3 -> 46074 | W3: =if(A3>V3,"Late", "On time") -> On time | X3: New Buy | Z3: Done | AA3: FATP-NPI-OR6-MVA2601-101OM | AB3: Done | AC3: 1FSHQ10134 | AD3: Done | AE3: 1FSHQ10134 | AG3: 46073 | AH3: EPR2602020006 | AJ3: =B3&G3&J3&N3&X3&AA3 -> FAEMonitor 12OR6New BuyFATP-NPI-OR6-MVA2601-101OM | AK3: =if(Z3="Done",$J3,0) -> 2 | AL3: =if(AB3="Done",$J3,0) -> 2 | AM3: =if(AD3="Done",$J3,0) -> 2 | AN3: =if(AG3<>"",$J3,0) -> 2
A4: 46037 | B4: WH | C4: Le Thi Lich | D4: V1525678 | E4: lichlt@fih-foxconn.com | F4: 4478 | G4: IPC+ | H4: =vlookup(G4,'Bidding list 26'!$B$4:$G$270,6,0) -> #N/A | I4: 14200000 | J4: 2 | K4: =I4*J4 -> 28400000 | L4: OR6 EVT | N4: OR6 | O4: FATP | P4: EVT | Q4: 46052 | R4: =Q4-A4 -> 15 | S4: {=INDEX('NONG Project Timeline-OPM updat'!$D$8:$I$65,MATCH(1,('NONG Project Timeline-OPM updat'!$B$8:$B$65=N4)*('NONG Project Timeline-OPM updat'!$C$8:$C$65=O4),0),MATCH(P4,'NONG Project Timeline-OPM updat'!$D$5:$I$5,0))-14} -> 46074 | T4: =S4-A4 -> 37 | U4: =IFERROR(VLOOKUP(G4,'Bidding list 26'!$B$2:$P$21,15,0),"") | V4: =S4-U4 -> 46074 | W4: =if(A4>V4,"Late", "On time") -> On time | X4: New Buy | Z4: Done | AA4: FATP-NPI-OR6-MVA2601-101OM | AB4: Done | AC4: 1FSHQ10132 | AD4: Done | AE4: 1FSHQ10132 | AG4: 46066 | AH4: EPR2602020007 : Done | AJ4: =B4&G4&J4&N4&X4&AA4 -> WHIPC+2OR6New BuyFATP-NPI-OR6-MVA2601-101OM | AK4: =if(Z4="Done",$J4,0) -> 2 | AL4: =if(AB4="Done",$J4,0) -> 2 | AM4: =if(AD4="Done",$J4,0) -> 2 | AN4: =if(AG4<>"",$J4,0) -> 2
A5: 46037 | B5: WH | C5: Le Thi Lich | D5: V1525678 | E5: lichlt@fih-foxconn.com | F5: 4478 | G5: Monitor 1 | H5: =vlookup(G5,'Bidding list 26'!$B$4:$G$270,6,0) -> DELL E2225HM, 21.5 inch HDMI cable, 3Yrs Wty | I5: 1980000 | J5: 2 | K5: =I5*J5 -> 3960000 | L5: OR6 EVT | N5: OR6 | O5: FATP | P5: EVT | Q5: 46052 | R5: =Q5-A5 -> 15 | S5: {=INDEX('NONG Project Timeline-OPM updat'!$D$8:$I$65,MATCH(1,('NONG Project Timeline-OPM updat'!$B$8:$B$65=N5)*('NONG Project Timeline-OPM updat'!$C$8:$C$65=O5),0),MATCH(P5,'NONG Project Timeline-OPM updat'!$D$5:$I$5,0))-14} -> 46074 | T5: =S5-A5 -> 37 | U5: =IFERROR(VLOOKUP(G5,'Bidding list 26'!$B$2:$P$21,15,0),"") | V5: =S5-U5 -> 46074 | W5: =if(A5>V5,"Late", "On time") -> On time | X5: New Buy | Z5: Done | AB5: Done | AD5: Done | AG5: 46073 | AH5: EPR2602020008 ( cũ ) | AJ5: =B5&G5&J5&N5&X5&AA5 -> WHMonitor 12OR6New Buy | AK5: =if(Z5="Done",$J5,0) -> 2 | AL5: =if(AB5="Done",$J5,0) -> 2 | AM5: =if(AD5="Done",$J5,0) -> 2 | AN5: =if(AG5<>"",$J5,0) -> 2
A6: 46037 | B6: WH | C6: Le Thi Lich | D6: V1525678 | E6: lichlt@fih-foxconn.com | F6: 4478 | G6: PDA CHAINWAY C61-4850 | H6: =vlookup(G6,'Bidding list 26'!$B$4:$G$270,6,0) -> C61-4850, Not including RFID module. Includes: 64GB 27-key Android 11, controller with battery, charging dock, charging adapter, glass screen protector | I6: 15500000 | J6: 1 | K6: =I6*J6 -> 15500000 | L6: OR6 EVT | N6: OR6 | O6: FATP | P6: EVT | Q6: 46084 | R6: =Q6-A6 -> 47 | S6: {=INDEX('NONG Project Timeline-OPM updat'!$D$8:$I$65,MATCH(1,('NONG Project Timeline-OPM updat'!$B$8:$B$65=N6)*('NONG Project Timeline-OPM updat'!$C$8:$C$65=O6),0),MATCH(P6,'NONG Project Timeline-OPM updat'!$D$5:$I$5,0))-14} -> 46074 | T6: =S6-A6 -> 37 | U6: =IFERROR(VLOOKUP(G6,'Bidding list 26'!$B$2:$P$21,15,0),"") -> 65 | V6: =S6-U6 -> 46009 | W6: =if(A6>V6,"Late", "On time") -> Late | X6: New Buy | Z6: Done | AA6: FATP-NPI-OR6-MVA2602-112OM | AB6: Done | AC6: VNPR202602090065 | AD6: Done | AE6: VNPO202602130022 | AG6: 46112 | AH6: EPR2603100002 | AJ6: =B6&G6&J6&N6&X6&AA6 -> WHPDA CHAINWAY C61-48501OR6New BuyFATP-NPI-OR6-MVA2602-112OM | AK6: =if(Z6="Done",$J6,0) -> 1 | AL6: =if(AB6="Done",$J6,0) -> 1 | AM6: =if(AD6="Done",$J6,0) -> 1 | AN6: =if(AG6<>"",$J6,0) -> 1
